{
 "cells": [
  {
   "cell_type": "code",
   "execution_count": 1,
   "id": "8363fe5e",
   "metadata": {},
   "outputs": [],
   "source": [
    "import os"
   ]
  },
  {
   "cell_type": "code",
   "execution_count": 2,
   "id": "212227fc",
   "metadata": {},
   "outputs": [
    {
     "data": {
      "text/plain": [
       "'c:\\\\Users\\\\Eric\\\\Documents\\\\LEARN2\\\\datascienceproject\\\\research'"
      ]
     },
     "execution_count": 2,
     "metadata": {},
     "output_type": "execute_result"
    }
   ],
   "source": [
    "%pwd"
   ]
  },
  {
   "cell_type": "code",
   "execution_count": 3,
   "id": "260af3f5",
   "metadata": {},
   "outputs": [
    {
     "data": {
      "text/plain": [
       "'c:\\\\Users\\\\Eric\\\\Documents\\\\LEARN2\\\\datascienceproject'"
      ]
     },
     "execution_count": 3,
     "metadata": {},
     "output_type": "execute_result"
    }
   ],
   "source": [
    "os.chdir(\"../\")\n",
    "%pwd"
   ]
  },
  {
   "cell_type": "code",
   "execution_count": 15,
   "id": "383deb40",
   "metadata": {},
   "outputs": [],
   "source": [
    "from dataclasses import dataclass \n",
    "from pathlib import Path \n",
    "\n",
    "@dataclass\n",
    "class DataIngestionConfig:\n",
    "    root_dir: Path\n",
    "    source_URL: str\n",
    "    local_data_file: Path \n",
    "    unzip_dir: Path \n"
   ]
  },
  {
   "cell_type": "code",
   "execution_count": 16,
   "id": "7f43223d",
   "metadata": {},
   "outputs": [],
   "source": [
    "from src.datascience.constants import *\n",
    "from src.datascience.utils.common import read_yaml, create_directories"
   ]
  },
  {
   "cell_type": "code",
   "execution_count": 17,
   "id": "ee78ed31",
   "metadata": {},
   "outputs": [],
   "source": [
    "class ConfigurationManager:\n",
    "    def __init__(self,\n",
    "                 config_filepath=CONFIG_FILE_PATH,\n",
    "                 params_filepath = PARAMS_FILE_PATH,\n",
    "                 schema_filepath = SCHEMA_FILE_PATH):\n",
    "        self.config=read_yaml(config_filepath)\n",
    "        self.config=read_yaml(params_filepath)\n",
    "        self.config=read_yaml(schema_filepath)\n",
    "\n",
    "        create_directories([self.config.artifacts_root])\n",
    "\n",
    "    def get_data_ingestion_config(self) -> DataIngestionConfig:\n",
    "        config=self.config.data_ingestion\n",
    "        create_directories([config.root_dir])\n",
    "\n",
    "        data_ingestion_config=DataIngestionConfig(\n",
    "            root_dir=config.root_dir,\n",
    "            source_URL=config.source_URL,\n",
    "            local_data_file=config.local_data_file,\n",
    "            unzip_dir=config.unzip_dir\n",
    "\n",
    "        )\n",
    "        return data_ingestion_config"
   ]
  },
  {
   "cell_type": "code",
   "execution_count": 18,
   "id": "94243819",
   "metadata": {},
   "outputs": [],
   "source": [
    "import os\n",
    "import urllib.request as request \n",
    "from src.datascience import logger \n",
    "import zipfile"
   ]
  },
  {
   "cell_type": "code",
   "execution_count": 19,
   "id": "a785fe64",
   "metadata": {},
   "outputs": [],
   "source": [
    "## component - data ingestion\n",
    "\n",
    "class DataIngestion:\n",
    "    def __init__(self, config:DataIngestionConfig):\n",
    "        self.config = config\n",
    "\n",
    "#Downloading the zip file\n",
    "    def download_file(self):\n",
    "        if not os.path.exists(self.config.local_data):\n",
    "            filename, headers = request.urlretrieve(\n",
    "                url = self.config.source_URL,\n",
    "                filename = self.config.local_data_file\n",
    "            )\n",
    "            logger.info(f\"{filename} download! with the following info: \\n{headers}\")\n",
    "        else:\n",
    "            logger.info(f\"File already exists\")\n",
    "\n",
    "    def extract_zip_file(self):\n",
    "\n",
    "        \"\"\" \n",
    "\n",
    "        Zip_file_path: str\n",
    "        Extracts the zip file into the data directory\n",
    "        Function returns None\n",
    "\n",
    "        \"\"\"\n",
    "\n",
    "        unzip_path = self.config.unzip_dir\n",
    "        os.makedirs(unzip_path, exist_ok=True)\n",
    "        with zipfile.ZipFile(self.config.local_data_file, 'r') as zip_ref:\n",
    "            zip_ref.extractall(unzip_path)\n",
    "        "
   ]
  },
  {
   "cell_type": "code",
   "execution_count": 21,
   "id": "88eb9a1d",
   "metadata": {},
   "outputs": [
    {
     "name": "stdout",
     "output_type": "stream",
     "text": [
      "[2025-09-29 22:25:09,977: INFO: common: yaml file: config\\config.yaml loaded successfully]\n",
      "[2025-09-29 22:25:09,993: INFO: common: yaml file: params.yaml loaded successfully]\n",
      "[2025-09-29 22:25:10,002: INFO: common: yaml file: schema.yaml loaded successfully]\n"
     ]
    },
    {
     "ename": "BoxKeyError",
     "evalue": "\"'ConfigBox' object has no attribute 'artifacts_root'\"",
     "output_type": "error",
     "traceback": [
      "\u001b[1;31m---------------------------------------------------------------------------\u001b[0m",
      "\u001b[1;31mKeyError\u001b[0m                                  Traceback (most recent call last)",
      "File \u001b[1;32mc:\\Users\\Eric\\Documents\\LEARN2\\datascienceproject\\venv\\lib\\site-packages\\box\\box.py:594\u001b[0m, in \u001b[0;36mbox.box.Box.__getitem__\u001b[1;34m()\u001b[0m\n",
      "\u001b[1;31mKeyError\u001b[0m: 'artifacts_root'",
      "\nThe above exception was the direct cause of the following exception:\n",
      "\u001b[1;31mBoxKeyError\u001b[0m                               Traceback (most recent call last)",
      "File \u001b[1;32mc:\\Users\\Eric\\Documents\\LEARN2\\datascienceproject\\venv\\lib\\site-packages\\box\\box.py:633\u001b[0m, in \u001b[0;36mbox.box.Box.__getattr__\u001b[1;34m()\u001b[0m\n",
      "File \u001b[1;32mc:\\Users\\Eric\\Documents\\LEARN2\\datascienceproject\\venv\\lib\\site-packages\\box\\box.py:621\u001b[0m, in \u001b[0;36mbox.box.Box.__getitem__\u001b[1;34m()\u001b[0m\n",
      "\u001b[1;31mBoxKeyError\u001b[0m: \"'artifacts_root'\"",
      "\nDuring handling of the above exception, another exception occurred:\n",
      "\u001b[1;31mAttributeError\u001b[0m                            Traceback (most recent call last)",
      "File \u001b[1;32mc:\\Users\\Eric\\Documents\\LEARN2\\datascienceproject\\venv\\lib\\site-packages\\box\\box.py:635\u001b[0m, in \u001b[0;36mbox.box.Box.__getattr__\u001b[1;34m()\u001b[0m\n",
      "\u001b[1;31mAttributeError\u001b[0m: 'ConfigBox' object has no attribute 'artifacts_root'",
      "\nThe above exception was the direct cause of the following exception:\n",
      "\u001b[1;31mBoxKeyError\u001b[0m                               Traceback (most recent call last)",
      "File \u001b[1;32mc:\\Users\\Eric\\Documents\\LEARN2\\datascienceproject\\venv\\lib\\site-packages\\box\\config_box.py:29\u001b[0m, in \u001b[0;36mbox.config_box.ConfigBox.__getattr__\u001b[1;34m()\u001b[0m\n",
      "File \u001b[1;32mc:\\Users\\Eric\\Documents\\LEARN2\\datascienceproject\\venv\\lib\\site-packages\\box\\box.py:649\u001b[0m, in \u001b[0;36mbox.box.Box.__getattr__\u001b[1;34m()\u001b[0m\n",
      "\u001b[1;31mBoxKeyError\u001b[0m: \"'ConfigBox' object has no attribute 'artifacts_root'\"",
      "\nDuring handling of the above exception, another exception occurred:\n",
      "\u001b[1;31mKeyError\u001b[0m                                  Traceback (most recent call last)",
      "File \u001b[1;32mc:\\Users\\Eric\\Documents\\LEARN2\\datascienceproject\\venv\\lib\\site-packages\\box\\box.py:594\u001b[0m, in \u001b[0;36mbox.box.Box.__getitem__\u001b[1;34m()\u001b[0m\n",
      "\u001b[1;31mKeyError\u001b[0m: 'artifacts_root'",
      "\nThe above exception was the direct cause of the following exception:\n",
      "\u001b[1;31mBoxKeyError\u001b[0m                               Traceback (most recent call last)",
      "File \u001b[1;32mc:\\Users\\Eric\\Documents\\LEARN2\\datascienceproject\\venv\\lib\\site-packages\\box\\box.py:633\u001b[0m, in \u001b[0;36mbox.box.Box.__getattr__\u001b[1;34m()\u001b[0m\n",
      "File \u001b[1;32mc:\\Users\\Eric\\Documents\\LEARN2\\datascienceproject\\venv\\lib\\site-packages\\box\\box.py:621\u001b[0m, in \u001b[0;36mbox.box.Box.__getitem__\u001b[1;34m()\u001b[0m\n",
      "\u001b[1;31mBoxKeyError\u001b[0m: \"'artifacts_root'\"",
      "\nDuring handling of the above exception, another exception occurred:\n",
      "\u001b[1;31mAttributeError\u001b[0m                            Traceback (most recent call last)",
      "File \u001b[1;32mc:\\Users\\Eric\\Documents\\LEARN2\\datascienceproject\\venv\\lib\\site-packages\\box\\box.py:635\u001b[0m, in \u001b[0;36mbox.box.Box.__getattr__\u001b[1;34m()\u001b[0m\n",
      "\u001b[1;31mAttributeError\u001b[0m: 'ConfigBox' object has no attribute 'artifacts_root'",
      "\nThe above exception was the direct cause of the following exception:\n",
      "\u001b[1;31mBoxKeyError\u001b[0m                               Traceback (most recent call last)",
      "Cell \u001b[1;32mIn[21], line 8\u001b[0m\n\u001b[0;32m      6\u001b[0m     data_ingestion\u001b[38;5;241m.\u001b[39mextract_zip_file()\n\u001b[0;32m      7\u001b[0m \u001b[38;5;28;01mexcept\u001b[39;00m \u001b[38;5;167;01mException\u001b[39;00m \u001b[38;5;28;01mas\u001b[39;00m e:\n\u001b[1;32m----> 8\u001b[0m     \u001b[38;5;28;01mraise\u001b[39;00m e \n",
      "Cell \u001b[1;32mIn[21], line 2\u001b[0m\n\u001b[0;32m      1\u001b[0m \u001b[38;5;28;01mtry\u001b[39;00m:\n\u001b[1;32m----> 2\u001b[0m     config \u001b[38;5;241m=\u001b[39m \u001b[43mConfigurationManager\u001b[49m\u001b[43m(\u001b[49m\u001b[43m)\u001b[49m\n\u001b[0;32m      3\u001b[0m     data_ingestion_config \u001b[38;5;241m=\u001b[39m config\u001b[38;5;241m.\u001b[39mget_data_ingestion_config()\n\u001b[0;32m      4\u001b[0m     data_ingestion \u001b[38;5;241m=\u001b[39m DataIngestion(config\u001b[38;5;241m=\u001b[39mdata_ingestion_config)\n",
      "Cell \u001b[1;32mIn[17], line 10\u001b[0m, in \u001b[0;36mConfigurationManager.__init__\u001b[1;34m(self, config_filepath, params_filepath, schema_filepath)\u001b[0m\n\u001b[0;32m      7\u001b[0m \u001b[38;5;28mself\u001b[39m\u001b[38;5;241m.\u001b[39mconfig\u001b[38;5;241m=\u001b[39mread_yaml(params_filepath)\n\u001b[0;32m      8\u001b[0m \u001b[38;5;28mself\u001b[39m\u001b[38;5;241m.\u001b[39mconfig\u001b[38;5;241m=\u001b[39mread_yaml(schema_filepath)\n\u001b[1;32m---> 10\u001b[0m create_directories([\u001b[38;5;28;43mself\u001b[39;49m\u001b[38;5;241;43m.\u001b[39;49m\u001b[43mconfig\u001b[49m\u001b[38;5;241;43m.\u001b[39;49m\u001b[43martifacts_root\u001b[49m])\n",
      "File \u001b[1;32mc:\\Users\\Eric\\Documents\\LEARN2\\datascienceproject\\venv\\lib\\site-packages\\box\\config_box.py:31\u001b[0m, in \u001b[0;36mbox.config_box.ConfigBox.__getattr__\u001b[1;34m()\u001b[0m\n",
      "File \u001b[1;32mc:\\Users\\Eric\\Documents\\LEARN2\\datascienceproject\\venv\\lib\\site-packages\\box\\box.py:649\u001b[0m, in \u001b[0;36mbox.box.Box.__getattr__\u001b[1;34m()\u001b[0m\n",
      "\u001b[1;31mBoxKeyError\u001b[0m: \"'ConfigBox' object has no attribute 'artifacts_root'\""
     ]
    }
   ],
   "source": [
    "try:\n",
    "    config = ConfigurationManager()\n",
    "    data_ingestion_config = config.get_data_ingestion_config()\n",
    "    data_ingestion = DataIngestion(config=data_ingestion_config)\n",
    "    data_ingestion.download_file()\n",
    "    data_ingestion.extract_zip_file()\n",
    "except Exception as e:\n",
    "    raise e "
   ]
  }
 ],
 "metadata": {
  "kernelspec": {
   "display_name": "Python 3",
   "language": "python",
   "name": "python3"
  },
  "language_info": {
   "codemirror_mode": {
    "name": "ipython",
    "version": 3
   },
   "file_extension": ".py",
   "mimetype": "text/x-python",
   "name": "python",
   "nbconvert_exporter": "python",
   "pygments_lexer": "ipython3",
   "version": "3.10.0"
  }
 },
 "nbformat": 4,
 "nbformat_minor": 5
}
